Workbook
Name _1: #REF!
Name _1: #REF!
Name _1: #REF!
Name _2: #REF!
Name _2: #REF!
Name _2: #REF!
Name _44: #REF!
Name _44: #REF!
Name _44: #REF!
Name a: #REF!
Name a: #REF!
Name a: #REF!
Name aa: #REF!
Name aa: #REF!
Name aa: #REF!
Name aaa: #REF!
Name aaa: #REF!
Name aaa: #REF!
Name aaaa: #REF!
Name APP: #REF!
Name b: #REF!
Name bb: #REF!
Name c_: #REF!
Name cc: #REF!
Name d: #REF!
Name dd: #REF!
Name e: #REF!
Name f: #REF!
Name ff: #REF!
Name fin: [2]CashFlow!#REF!
Name fin: [3]CashFlow!#REF!
Name fin: [4]CashFlow!#REF!
Name finn: [2]CashFlow!#REF!
Name finn: [3]CashFlow!#REF!
Name finn: [4]CashFlow!#REF!
Name g: Assumpt!$A$2:$W$84
Name h: #REF!
Name h: #REF!
Name h: #REF!
Name HD_VEH_POP_by_Phase_veh_power: #REF!
Name HD_VEH_POP_by_Phase_veh_power: #REF!
Name HD_VEH_POP_by_Phase_veh_power: #REF!
Name j: #REF!
Name j: #REF!
Name j: #REF!
Name m: #REF!
Name modelyear_inspected_by_year: #REF!
Name nn: #REF!
Name PTSum: [5]Summary!#REF!
Name PTSum: [5]Summary!#REF!
Name PTSum: [5]Summary!#REF!
Name rate: '[6]IT Hours'!$K$3:$L$6
Name Rate1: '[6]IT Hours'!$L$3:$M$6
Name rates: [7]Sheet1!$A$72:$D$78
Name rgData: #REF!
Name rgData: #REF!
Name rgData: #REF!
Name rgDataDate: #REF!
Name rgDataDate: #REF!
Name rgDataDate: #REF!

Sheet Assumpt
A1: New Jersey Enhanced Motor Vehicle Inspection/Maintenance Systems
A2: NJ Vehicle Inspection Program
A4: General Project Information:
A5: Proposal Number:
A6: Client: | C6: State of New Jersey
A7: Project Description: | C7: =A1 -> New Jersey Enhanced Motor Vehicle Inspection/Maintenance Systems
A8: Project Manager: | C8: Arden Clark
A9: Proposal Manager:
A10: Implementation Project Manager: | C10: Arden Clark
A11: Start Date: | C11: 44136
A12: Date Contract Starts - Paid Tests: | C12: 42491
A13: Completion Date: | C13: 46113
A14: Contract Duration: | C14: 6 Years | D14: =6*12-3 -> 69
A15: Extension Options | C15: 2, Two Year Extensions | D15: 48 Months
A16: Currency: | C16: US Dollars | D16: 117 Months total
A18: ****All Prices should NOT include tax
A22: SCOPE:
A23: VID Development
A24: PIF's and PFF's
A25: CIF's
A26: PIF Equipment
A28: xxxxxxxxxxxxxxxxxxxxxxxxxxxxxxxxxxxxxxxxxxxxxxxxxxxxxxxxxxxxxxxx | C28: xxxxxxxxxxxxxxxxxxxxxxxxxxxxxxxxxxxxxxxxxxxxxxxxx | D28: xxxxxxxxxxxxxxxxxxxxxxxxxxxxxxxxxxxxxxxxxxxxxxxxx | E28: xxxxxxxxxxxxxxxxxxxxxxxxxxxxxxxxxxxxxxxxxxxxxxxxx | F28: xxxxxxxxxxxxxxxxxxxxxxxxxxxxxxxxxxxxxxxxxxxxxxxxx | G28: xxxxxxxxxxxxxxxxxxxxxxxxxxxxxxxxxxxxxxxxxxxxxxxxx | H28: xxxxxxxxxxxxxxxxxxxxxxxxxxxxxxxxxxxxxxxxxxxxxxxxx | I28: xxxxxxxxxxxxxxxxxxxxxxxxxxxxxxxxxxxxxxxxxxxxxxxxx | J28: xxxxxxxxxxxxxxxxxxxxxxxxxxxxxxxxxxxxxxxxxxxxxxxxx | N28: xxxxxxxxxxxxxxxxxxxxxxxxxxxxxxxxxxxxxxxxxxxxxxxxx
C31: Original Contract Term | J31: Spare | K31: Spare | L31: Spare | M31: Spare
A32: Periods Assumed in Model: | C32: Start-up | D32: Year 1 | E32: Year 2 | F32: Year 3 | G32: Year 4 | H32: Year 5 | I32: Year 6 | J32: Year 7 | K32: Year 8 | L32: Year 9 | M32: Year 10 | N32: Grand Total
C33: 0 | D33: 9 | E33: 12 | F33: 12 | G33: 12 | H33: 12 | I33: 12 | J33: 12 | K33: 12 | L33: 12 | M33: 12 | N33: =SUM(D33:M33) -> 117
C34: Nov 2019 apr 2020 | D34: May 2020 Jan 2021 | E34: Feb 2021 Jan 2022 | F34: Feb 2022 Jan 2023 | G34: Feb 2024 Jan 2024 | H34: Feb 2024 Jan 2025 | I34: Feb 2025 Jan 2026 | J34: Feb 2026 Jan 2027 | K34: Feb 2027 Jan 2028 | L34: Feb 2028 Jan 2029 | M34: Feb 2029 Jan 2030 | N34: Years 1
N35: Thru 10
A38: Labor inflation | C38: 1 | D38: 1 | E38: 1.03 | F38: 1.03 | G38: 1.03 | H38: 1.03 | I38: 1 | J38: 1 | K38: 1 | L38: 1 | M38: 1
A39: Labor inflation cumulative | C39: 1 | D39: 1 | E39: =E38 -> 1.03 | F39: =E39*F38 -> 1.0609 | G39: =F39*G38 -> 1.092727 | H39: =G39*H38 -> 1.1255088 | I39: =H39*I38 -> 1.1255088 | J39: =I39*J38 -> 1.1255088 | K39: =J39*K38 -> 1.1255088 | L39: =K39*L38 -> 1.1255088 | M39: =L39*M38 -> 1.1255088
A40: ODC inflation | C40: 1 | D40: 1 | E40: 1 | F40: 1 | G40: 1 | H40: 1 | I40: 1 | J40: 1 | K40: 1 | L40: 1 | M40: 1
A41: ODC inflation cumulative | C41: 1 | D41: 1 | E41: 1 | F41: =E41*F40 -> 1 | G41: =F41*G40 -> 1 | H41: =G41*H40 -> 1 | I41: =H41*I40 -> 1 | J41: =I41*J40 -> 1 | K41: =J41*K40 -> 1 | L41: =K41*L40 -> 1 | M41: =L41*M40 -> 1
A42: Union Labor inflation | C42: 1 | D42: 1 | E42: 1.03 | F42: 1.01 | G42: 1.01 | H42: 1.01 | I42: 1.01 | J42: 1.01 | K42: 1.01 | L42: 1.01 | M42: 1.01
D45: Parsons | I45: Union
A46: Hours Worked per Year | D46: Days | E46: Hours | I46: Days | J46: Hours | K46: Per Month
A47: Total Work Hours | D47: =E47/8 -> 260 | E47: =52*40 -> 2080 | H47: Full Time | I47: =J47/8 -> 212 | J47: =8*5*42+16 -> 1696 | K47: =J47/12 -> 141.33333 | L47: ** Assumes 5 weeks vacation + 2 weeks sick + 13 holidays
A48: Paid Vacation - Statutory Holiday | D48: =E48/8 -> 8 | E48: =8*8 -> 64 | H48: Part Time | I48: =J48/8 -> 133.25 | J48: =5*5*42+16 -> 1066 | K48: =J48/12 -> 88.833333 | L48: ***4 weeks vacation+
A49: PTO - Vacation/Sick/Bereavement/Military | D49: 15 | E49: =15*8 -> 120 | H49: Warehouse | I49: =J49/8 -> 240 | J49: =8*5*48 -> 1920
A50: Total Work Less Fringe | D50: =D47-D48-D49 -> 237 | E50: =ROUND(E47-E48-E49,0) -> 1896 | I50: =SUM(I47:I49) -> 585.25 | J50: =SUM(J47:J49) -> 4682
J52: =AVERAGE(J47,J48,J49) -> 1560.6667
A54: xxxxxxxxxxxxxxxxxxxxxxxxxxxxxxxxxxxxxxxxxxxxxxxxx | C54: xxxxxxxxxxxxxxxxxxxxxxxxxxxxxxxxxxxxxxxxxxxxxxxxx | D54: xxxxxxxxxxxxxxxxxxxxxxxxxxxxxxxxxxxxxxxxxxxxxxxxx | E54: xxxxxxxxxxxxxxxxxxxxxxxxxxxxxxxxxxxxxxxxxxxxxxxxx | F54: xxxxxxxxxxxxxxxxxxxxxxxxxxxxxxxxxxxxxxxxxxxxxxxxx | G54: xxxxxxxxxxxxxxxxxxxxxxxxxxxxxxxxxxxxxxxxxxxxxxxxx | H54: xxxxxxxxxxxxxxxxxxxxxxxxxxxxxxxxxxxxxxxxxxxxxxxxx | I54: xxxxxxxxxxxxxxxxxxxxxxxxxxxxxxxxxxxxxxxxxxxxxxxxx | J54: xxxxxxxxxxxxxxxxxxxxxxxxxxxxxxxxxxxxxxxxxxxxxxxxx | N54: xxxxxxxxxxxxxxxxxxxxxxxxxxxxxxxxxxxxxxxxxxxxxxxxx | O54: xxxxxxxxxxxxxxxxxxxxxxxxxxxxxxxxxxxxxxxxxxxxxxxxx | P54: xxxxxxxxxxxxxxxxxxxxxxxxxxxxxxxxxxxxxxxxxxxxxxxxx | Q54: xxxxxxxxxxxxxxxxxxxxxxxxxxxxxxxxxxxxxxxxxxxxxxxxx | R54: xxxxxxxxxxxxxxxxxxxxxxxxxxxxxxxxxxxxxxxxxxxxxxxxx | S54: xxxxxxxxxxxxxxxxxxxxxxxxxxxxxxxxxxxxxxxxxxxxxxxxx | T54: xxxxxxxxxxxxxxxxxxxxxxxxxxxxxxxxxxxxxxxxxxxxxxxxx | U54: xxxxxxxxxxxxxxxxxxxxxxxxxxxxxxxxxxxxxxxxxxxxxxxxx | V54: xxxxxxxxxxxxxxxxxxxxxxxxxxxxxxxxxxxxxxxxxxxxxxxxx | W54: xxxxxxxxxxxxxxxxxxxxxxxxxxxxxxxxxxxxxxxxxxxxxxxxx | X54: xxxxxxxxxxxxxxxxxxxxxxxxxxxxxxxxxxxxxxxxxxxxxxxxx | Y54: xxxxxxxxxxxxxxxxxxxxxxxxxxxxxxxxxxxxxxxxxxxxxxxxx | Z54: xxxxxxxxxxxxxxxxxxxxxxxxxxxxxxxxxxxxxxxxxxxxxxxxx | AA54: xxxxxxxxxxxxxxxxxxxxxxxxxxxxxxxxxxxxxxxxxxxxxxxxx | AB54: xxxxxxxxxxxxxxxxxxxxxxxxxxxxxxxxxxxxxxxxxxxxxxxxx
...

Sheet Pricing details
G1: Pricing and Labor Cost Sheet
O2: Fringe | AQ2: 200 | AR2: 96 | AU2: =AQ2*AR2 -> 19200 | AV2: 1
N3: ***Hourly rate in US $ | O3: CDN | AL3: =18585*18+57390 -> 391920 | AQ3: 1600 | AR3: 12 | AU3: =AQ3*AR3 -> 19200
O4: US | AL4: =3229/56890 -> 0.056758657
C5: 75196 | D5: 18 | E5: =C5*D5 -> 1353528 | O5: US-lite | Q5: Inflation
E6: =199551*18 -> 3591918 | O6: Acerage | Q6: Labor
Q7: ODC's
C9: MBE Type | D9: Company Nmae | E9: Cashflow Category | F9: Scope | G9: Section | H9: Price line and cost type | I9: Cost Type | J9: Description | K9: Price sheet line item | L9: x2 | M9: Cost Per Hour/Unit | N9: Fringe Rate | O9: Headcount/hours | P9: Month 1 | Q9: Month 2 | R9: Month 3 | S9: Month 4 | T9: Month 5 | U9: Month 6 | V9: Month 7 | W9: Month 8 | X9: Startup up totals | Y9: Year 1 | Z9: Year 2 | AA9: Year 3 | AB9: Year 4 | AC9: Year 5 | AD9: Year 6 | AE9: Year 7 | AF9: Year 8 | AG9: Year 9 | AH9: Year 10 | AI9: TOTAL UNITS | AJ9: total hours | AK9: x | AL9: startup | AM9: =CONCATENATE(Y9," Costs") -> Year 1 Costs | AN9: =CONCATENATE(Z9," Costs") -> Year 2 Costs | AO9: Year 3 costs | AP9: Year 4 costs | AQ9: Year 5 costs | AR9: Year 6 costs | AS9: Total costs Years 1 - 6 | AU9: Year 7 costs | AV9: Year 8 costs | AW9: Year 9 costs | AX9: Year 10 costs | AY9: Total costs Years 7-10 | AZ9: Total costs Years 0-10
A11: Canadian Labor
B12: Development Canada | H12: =CONCATENATE(K12,I12) -> 1Labor | I12: Labor | J12: =B12 -> Development Canada | K12: 1 | M12: =120000/2080*0.75 -> 43.269231 | O12: ='Application Development'!E163 -> 1683.825 | X12: =SUM(P12:W12) -> 0 | Y12: 1690 | AI12: =SUM(Y12:AH12) -> 1690 | AJ12: =AI12+X12 -> 1690 | AL12: =$M12*(1+$N12)*X12*Assumpt!C$39 -> 0 | AM12: =$M12*(1+$N12)*Y12*Assumpt!D$39 -> 73125 | AN12: =$M12*(1+P12)*Z12*Assumpt!E$39 -> 0 | AO12: =P12*(1+Q12)*AA12*Assumpt!F39 -> 0 | AP12: =Q12*(1+R12)*AB12*Assumpt!G39 -> 0 | AQ12: =R12*(1+S12)*AC12*Assumpt!H39 -> 0 | AR12: =S12*(1+T12)*AD12*Assumpt!I39 -> 0 | AS12: =SUM(AM12:AR12) -> 73125 | AU12: =T12*(1+U12)*AE12*Assumpt!J39 -> 0 | AV12: =U12*(1+V12)*AF12*Assumpt!K39 -> 0 | AW12: =V12*(1+W12)*AG12*Assumpt!L39 -> 0 | AX12: =W12*(1+X12)*AH12*Assumpt!M39 -> 0 | AY12: =SUM(AU12:AX12) -> 0 | AZ12: =AL12+AS12+AY12 -> 73125 | BC12: =AV12-AU12 -> 0
B13: Development Canada | H13: =CONCATENATE(K13,I13) -> 2Labor | I13: Labor | J13: =B13 -> Development Canada | K13: 2 | M13: =120000/2080*0.75 -> 43.269231 | O13: ='Application Development'!F163 -> 6735.3 | X13: =SUM(P13:W13) -> 0 | Y13: 6735 | AI13: =SUM(Y13:AH13) -> 6735 | AJ13: =AI13+X13 -> 6735 | AL13: =$M13*(1+$N13)*X13*Assumpt!C$39 -> 0 | AM13: =$M13*(1+$N13)*Y13*Assumpt!D$39 -> 291418.27 | AN13: =$M13*(1+P13)*Z13*Assumpt!E$39 -> 0 | AO13: =P13*(1+Q13)*AA13*Assumpt!F40 -> 0 | AP13: =Q13*(1+R13)*AB13*Assumpt!G40 -> 0 | AQ13: =R13*(1+S13)*AC13*Assumpt!H40 -> 0 | AR13: =S13*(1+T13)*AD13*Assumpt!I40 -> 0 | AS13: =SUM(AM13:AR13) -> 291418.27 | AU13: =T13*(1+U13)*AE13*Assumpt!J40 -> 0 | AV13: =U13*(1+V13)*AF13*Assumpt!K40 -> 0 | AW13: =V13*(1+W13)*AG13*Assumpt!L40 -> 0 | AX13: =W13*(1+X13)*AH13*Assumpt!M40 -> 0 | AY13: =SUM(AU13:AX13) -> 0 | AZ13: =AL13+AS13+AY13 -> 291418.27 | BC13: =AV13-AU13 -> 0
B14: Support Canada | H14: =CONCATENATE(K14,I14) -> 11Labor | I14: Labor | J14: =B14 -> Support Canada | K14: 11 | M14: =120000/2080*0.75 -> 43.269231 | O14: 0 | X14: =SUM(P14:W14) -> 0 | Y14: =$O$14*Assumpt!$E$50 -> 0 | Z14: =$O$14*Assumpt!$E$50 -> 0 | AA14: =$O$14*Assumpt!$E$50 -> 0 | AB14: =$O$14*Assumpt!$E$50 -> 0 | AC14: =$O$14*Assumpt!$E$50 -> 0 | AD14: =$O$14*Assumpt!$E$50 -> 0 | AE14: =$O$14*Assumpt!$E$50 -> 0 | AF14: =$O$14*Assumpt!$E$50 -> 0 | ... AH14: =$O$14*Assumpt!$E$50 -> 0 | AI14: =SUM(Y14:AH14) -> 0 | AJ14: =AI14+X14 -> 0 | AL14: =$M14*(1+$N14)*X14*Assumpt!C$39 -> 0 | AM14: =$M14*(1+$N14)*Y14*Assumpt!D$39 -> 0 | AS14: =SUM(AM14:AR14) -> 0 | AY14: =SUM(AU14:AX14) -> 0 | AZ14: =AL14+AS14+AY14 -> 0 | BC14: =AV14-AU14 -> 0
B15: Support Canada | H15: =CONCATENATE(K15,I15) -> 11Labor | I15: Labor | J15: =B15 -> Support Canada | K15: 11 | M15: =120000/2080*0.75 -> 43.269231 | O15: 1.5 | X15: =SUM(P15:W15) -> 0 | Y15: =$O$15*Assumpt!$E$50 -> 2844 | Z15: =$O$15*Assumpt!$E$50 -> 2844 | AA15: =$O$15*Assumpt!$E$50 -> 2844 | AB15: =$O$15*Assumpt!$E$50 -> 2844 | AC15: =$O$15*Assumpt!$E$50 -> 2844 | AD15: =$O$15*Assumpt!$E$50 -> 2844 | AE15: =$O$15*Assumpt!$E$50 -> 2844 | AF15: =$O$15*Assumpt!$E$50 -> 2844 | ... AH15: =$O$15*Assumpt!$E$50 -> 2844 | AI15: =SUM(Y15:AH15) -> 28440 | AJ15: =AI15+X15 -> 28440 | AL15: =$M15*(1+$N15)*X15*Assumpt!C$39 -> 0 | AM15: =$M15*(1+$N15)*Y15*Assumpt!D$39 -> 123057.69 | AN15: =$M15*(1+$N15)*Z15*Assumpt!E$39 -> 126749.42 | AO15: =$M15*(1+$N15)*AA15*Assumpt!F$39 -> 130551.91 | AP15: =$M15*(1+$N15)*AB15*Assumpt!G$39 -> 134468.46 | AQ15: =$M15*(1+$N15)*AC15*Assumpt!H$39 -> 138502.52 | AR15: =$M15*(1+$N15)*AD15*Assumpt!I$39 -> 138502.52 | AS15: =SUM(AM15:AR15) -> 791832.52 | AU15: =$M15*(1+$N15)*AE15*Assumpt!J$39 -> 138502.52 | AV15: =$M15*(1+$N15)*AF15*Assumpt!K$39 -> 138502.52 | AW15: =$M15*(1+$N15)*AG15*Assumpt!L$39 -> 138502.52 | AX15: =SUM(AU15:AW15) -> 415507.55 | AY15: =SUM(AU15:AX15) -> 831015.1 | AZ15: =AL15+AS15+AY15 -> 1622847.6 | BC15: =AV15-AU15 -> 0
B16: Fringe | H16: =CONCATENATE(K16,I16) -> 11Labor | I16: Labor | J16: canada Fringe | K16: 11 | M16: =120000/2080*0.75 -> 43.269231 | N16: 0.3 | AL16: =SUM(AL12:AL15)*$N$16 -> 0 | AM16: =SUM(AM12:AM15)*$N$16 -> 146280.29 | AN16: =SUM(AN12:AN15)*$N$16 -> 38024.827 | AO16: =SUM(AO12:AO15)*$N$16 -> 39165.572 | AP16: =SUM(AP12:AP15)*$N$16 -> 40340.539 | AQ16: =SUM(AQ12:AQ15)*$N$16 -> 41550.755 | AR16: =SUM(AR12:AR15)*$N$16 -> 41550.755 | AS16: =SUM(AM16:AR16) -> 346912.74 | AU16: =SUM(AU12:AU15)*$N$16 -> 41550.755 | AV16: =SUM(AV12:AV15)*$N$16 -> 41550.755 | AW16: =SUM(AW12:AW15)*$N$16 -> 41550.755 | AX16: =SUM(AX12:AX15)*$N$16 -> 124652.27 | AY16: =SUM(AU16:AX16) -> 249304.53 | AZ16: =AL16+AS16+AY16 -> 596217.27 | BC16: =AV16-AU16 -> 0
A17: US labor | H17: =CONCATENATE(K17,I17) | AS17: =SUM(AM17:AR17) -> 0 | AY17: =SUM(AU17:AX17) -> 0 | AZ17: =AL17+AS17+AY17 -> 0 | BC17: =AV17-AU17 -> 0
B18: MGT | H18: =CONCATENATE(K18,I18) -> 11Labor | I18: Labor | J18: MGT | K18: 11 | Y18: 100360 | Z18: 133640 | AA18: =Z18 -> 133640 | AB18: =AA18 -> 133640 | AC18: =AB18 -> 133640 | AD18: =AC18 -> 133640 | AE18: =AD18 -> 133640 | AF18: =AE18 -> 133640 | AG18: =AF18 -> 133640 | AH18: =AG18 -> 133640 | AI18: =SUM(Y18:AH18) -> 1303120 | AJ18: =AI18+X18 -> 1303120 | AM18: =3734738.36177112*0.9 -> 3361264.5 | AN18: =5070844.87466104*0.8 -> 4056675.9 | AO18: =AN18*Assumpt!F38 -> 4178376.2 | AP18: =AO18*Assumpt!G38 -> 4303727.5 | AQ18: =AP18*Assumpt!H38 -> 4432839.3 | AR18: =AQ18*Assumpt!I38 -> 4432839.3 | AS18: =SUM(AM18:AR18) -> 24765723 | AU18: =AR18*Assumpt!J38 -> 4432839.3 | AV18: =AU18*Assumpt!K38 -> 4432839.3 | AW18: =AV18*Assumpt!L38 -> 4432839.3 | AX18: =AW18*Assumpt!M38 -> 4432839.3 | AY18: =SUM(AU18:AX18) -> 17731357 | AZ18: =AL18+AS18+AY18 -> 42497080 | BC18: =AV18-AU18 -> 0
B19: Union | H19: =CONCATENATE(K19,I19) -> 11Labor | I19: Labor | J19: Union | K19: 11 | Y19: 315380.78 | Z19: 424064 | AA19: =Z19 -> 424064 | AB19: =AA19 -> 424064 | AC19: =AB19 -> 424064 | AD19: =AC19 -> 424064 | AE19: =AD19 -> 424064 | AF19: =AE19 -> 424064 | AG19: =AF19 -> 424064 | AH19: =AG19 -> 424064 | AI19: =SUM(Y19:AH19) -> 4131956.8 | AJ19: =AI19+X19 -> 4131956.8 | AM19: =AN19*0.75 -> 6789354 | AN19: 9052472 | AO19: =AN19*Assumpt!F42 -> 9142996.7 | AP19: =AO19*Assumpt!G42 -> 9234426.7 | AQ19: =AP19*Assumpt!H42 -> 9326771 | AR19: =AQ19*Assumpt!I42 -> 9420038.7 | AS19: =SUM(AM19:AR19) -> 52966059 | AU19: =AR19*Assumpt!J42 -> 9514239.1 | AV19: =AU19*Assumpt!K42 -> 9609381.4 | AW19: =AV19*Assumpt!L42 -> 9705475.3 | AX19: =AW19*Assumpt!M42 -> 9802530 | AY19: =SUM(AU19:AX19) -> 38631626 | AZ19: =AL19+AS19+AY19 -> 91597685 | BC19: =AV19-AU19 -> 95142.391
B20: Union Fringe | H20: =CONCATENATE(K20,I20) -> 11Labor | I20: Labor | J20: MGT Fringe | K20: 11 | N20: 0.4025 | AM20: =$N$20*AM18 -> 1352909 | AN20: =$N$20*AN18 -> 1632812 | AO20: =$N$20*AO18 -> 1681796.4 | AP20: =$N$20*AP18 -> 1732250.3 | AQ20: =$N$20*AQ18 -> 1784217.8 | AR20: =$N$20*AR18 -> 1784217.8 | AS20: =SUM(AM20:AR20) -> 9968203.4 | AU20: =$N$20*AU18 -> 1784217.8 | AV20: =$N$20*AV18 -> 1784217.8 | AW20: =$N$20*AW18 -> 1784217.8 | AX20: =$N$20*AX18 -> 1784217.8 | AY20: =SUM(AU20:AX20) -> 7136871.3 | AZ20: =AL20+AS20+AY20 -> 17105075 | BC20: =AV20-AU20 -> 0
B21: Union Fringe | H21: =CONCATENATE(K21,I21) -> 11Labor | I21: Labor | J21: Union Fringe | K21: 11 | N21: 0.63 | AM21: =$N$21*AM19 -> 4277293 | AN21: =$N$21*AN19 -> 5703057.4 | AO21: =$N$21*AO19 -> 5760087.9 | AP21: =$N$21*AP19 -> 5817688.8 | AQ21: =$N$21*AQ19 -> 5875865.7 | AR21: =$N$21*AR19 -> 5934624.4 | AS21: =SUM(AM21:AR21) -> 33368617 | AU21: =$N$21*AU19 -> 5993970.6 | AV21: =$N$21*AV19 -> 6053910.3 | AW21: =$N$21*AW19 -> 6114449.4 | AX21: =$N$21*AX19 -> 6175593.9 | AY21: =SUM(AU21:AX21) -> 24337924 | AZ21: =AL21+AS21+AY21 -> 57706541 | BC21: =AV21-AU21 -> 59939.706
H22: =CONCATENATE(K22,I22) | AS22: =SUM(AM22:AR22) -> 0 | AY22: =SUM(AU22:AX22) -> 0 | AZ22: =AL22+AS22+AY22 -> 0 | BC22: =AV22-AU22 -> 0
H23: =CONCATENATE(K23,I23) | AS23: =SUM(AM23:AR23) -> 0 | AY23: =SUM(AU23:AX23) -> 0 | AZ23: =AL23+AS23+AY23 -> 0 | BC23: =AV23-AU23 -> 0
A24: ODCS | H24: =CONCATENATE(K24,I24) | AS24: =SUM(AM24:AR24) -> 0 | AY24: =SUM(AU24:AX24) -> 0 | AZ24: =AL24+AS24+AY24 -> 0 | BC24: =AV24-AU24 -> 0
H25: =CONCATENATE(K25,I25) -> 9Capital | I25: Capital | J25: Infrastructure one time | K25: 9 | M25: =infrastructure!P86*0.6 -> 658723.95 | Y25: 1 | AL25: =$M25*(1+$N25)*X25*Assumpt!C$39 -> 0 | AM25: =$M25*(1+$N25)*Y25*Assumpt!D$41 -> 658723.95 | AS25: =SUM(AM25:AR25) -> 658723.95 | AY25: =SUM(AU25:AX25) -> 0 | AZ25: =AL25+AS25+AY25 -> 658723.95 | BC25: =AV25-AU25 -> 0
H26: =CONCATENATE(K26,I26) -> 11ODCS | I26: ODCS | J26: Infrastructure recurring | K26: 11 | M26: =infrastructure!T86 -> 610708.4 | Y26: 1 | Z26: 1 | AA26: 1 | AB26: 1 | AC26: 1 | AD26: 1 | AE26: 1 | AF26: 1 | AG26: 1 | AH26: 1 | AL26: =$M26*(1+$N26)*X26*Assumpt!C$39 -> 0 | AM26: =$M26*(1+$N26)*Y26*Assumpt!D$41 -> 610708.4 | AN26: =infrastructure!W86 -> 568790.9 | AO26: =infrastructure!X86 -> 574315.9 | AP26: =infrastructure!Y86 -> 574315.9 | AQ26: =$M26*(1+$N26)*AC26*Assumpt!H$41 -> 610708.4 | AR26: =$M26*(1+$N26)*AD26*Assumpt!I$41 -> 610708.4 | AS26: =SUM(AM26:AR26) -> 3549547.9 | AU26: =$M26*(1+$N26)*AE26*Assumpt!J$41 -> 610708.4 | AV26: =$M26*(1+$N26)*AF26*Assumpt!K$41 -> 610708.4 | AW26: =$M26*(1+$N26)*AG26*Assumpt!L$41 -> 610708.4 | AX26: =$M26*(1+$N26)*AH26*Assumpt!M$41 -> 610708.4 | AY26: =SUM(AU26:AX26) -> 2442833.6 | AZ26: =AL26+AS26+AY26 -> 5992381.5 | BC26: =AV26-AU26 -> 0
H27: =CONCATENATE(K27,I27) -> 11Capital | I27: Capital | J27: Infrastructure refresh | K27: 11 | M27: =infrastructure!AB81 -> 434200 | AE27: 1 | AL27: =$M27*(1+$N27)*X27*Assumpt!C$39 -> 0 | AS27: =SUM(AM27:AR27) -> 0 | AU27: =$M27*(1+$N27)*AE27 -> 434200 | AY27: =SUM(AU27:AX27) -> 434200 | AZ27: =AL27+AS27+AY27 -> 434200 | BC27: =AV27-AU27 -> -434200
A28: Facility | H28: =CONCATENATE(K28,I28) | AS28: =SUM(AM28:AR28) -> 0 | AY28: =SUM(AU28:AX28) -> 0 | AZ28: =AL28+AS28+AY28 -> 0 | BC28: =AV28-AU28 -> 0
H29: =CONCATENATE(K29,I29) | AS29: =SUM(AM29:AR29) -> 0 | AY29: =SUM(AU29:AX29) -> 0 | AZ29: =AL29+AS29+AY29 -> 0 | BC29: =AV29-AU29 -> 0
H30: =CONCATENATE(K30,I30) | AS30: =SUM(AM30:AR30) -> 0 | AY30: =SUM(AU30:AX30) -> 0 | AZ30: =AL30+AS30+AY30 -> 0 | BC30: =AV30-AU30 -> 0
H31: =CONCATENATE(K31,I31) | AS31: =SUM(AM31:AR31) -> 0 | AY31: =SUM(AU31:AX31) -> 0 | AZ31: =AL31+AS31+AY31 -> 0 | BC31: =AV31-AU31 -> 0
H32: =CONCATENATE(K32,I32) -> 11ODCS | I32: ODCS | J32: Cyber security BOND | K32: 11 | M32: 0 | Y32: 1 | Z32: 1 | AA32: 1 | AB32: 1 | AC32: 1 | AD32: 1 | AE32: 1 | AF32: 1 | AG32: 1 | AH32: 1 | AL32: =$M32*(1+$N32)*X32*Assumpt!C$39 -> 0 | AN32: =$M32*(1+$N32)*Z32*Assumpt!E$41 -> 0 | AO32: =$M32*(1+$N32)*AA32*Assumpt!F$41 -> 0 | AP32: =$M32*(1+$N32)*AB32*Assumpt!G$41 -> 0 | AQ32: =$M32*(1+$N32)*AC32*Assumpt!H$41 -> 0 | AR32: =$M32*(1+$N32)*AD32*Assumpt!I$41 -> 0 | AS32: =SUM(AM32:AR32) -> 0 | AU32: =$M32*(1+$N32)*AE32*Assumpt!J$39 -> 0 | AV32: =$M32*(1+$N32)*AF32*Assumpt!K$39 -> 0 | AW32: =$M32*(1+$N32)*AG32*Assumpt!L$39 -> 0 | AX32: =$M32*(1+$N32)*AH32*Assumpt!M$39 -> 0 | AY32: =SUM(AU32:AX32) -> 0 | AZ32: =AL32+AS32+AY32 -> 0 | BC32: =AV32-AU32 -> 0
H33: =CONCATENATE(K33,I33) -> 11ODCS | I33: ODCS | J33: Insurance | K33: 11 | M33: 0 | Y33: 0.75 | Z33: 1 | AA33: 1 | AB33: 1 | AC33: 1 | AD33: 1 | AE33: 1 | AF33: 1 | AG33: 1 | AH33: 1 | AL33: =$M33*(1+$N33)*X33*Assumpt!C$39 -> 0 | AN33: =$M33*(1+$N33)*Z33*Assumpt!E$41 -> 0 | AO33: =$M33*(1+$N33)*AA33*Assumpt!F$41 -> 0 | AP33: =$M33*(1+$N33)*AB33*Assumpt!G$41 -> 0 | AQ33: =$M33*(1+$N33)*AC33*Assumpt!H$41 -> 0 | AR33: =$M33*(1+$N33)*AD33*Assumpt!I$41 -> 0 | AS33: =SUM(AM33:AR33) -> 0 | AU33: =$M33*(1+$N33)*AE33*Assumpt!J$39 -> 0 | AV33: =$M33*(1+$N33)*AF33*Assumpt!K$39 -> 0 | AW33: =$M33*(1+$N33)*AG33*Assumpt!L$39 -> 0 | AX33: =$M33*(1+$N33)*AH33*Assumpt!M$39 -> 0 | AY33: =SUM(AU33:AX33) -> 0 | AZ33: =AL33+AS33+AY33 -> 0 | BC33: =AV33-AU33 -> 0
H34: =CONCATENATE(K34,I34) -> 11ODCS | I34: ODCS | J34: Security testing | K34: 11 | M34: 0 | Y34: 1 | Z34: 1 | AA34: 1 | AB34: 1 | AC34: 1 | AD34: 1 | AE34: 1 | AF34: 1 | AG34: 1 | AH34: 1 | AL34: =$M34*(1+$N34)*X34*Assumpt!C$39 -> 0 | AN34: =$M34*(1+$N34)*Z34*Assumpt!E$41 -> 0 | AO34: =$M34*(1+$N34)*AA34*Assumpt!F$41 -> 0 | AP34: =$M34*(1+$N34)*AB34*Assumpt!G$41 -> 0 | AQ34: =$M34*(1+$N34)*AC34*Assumpt!H$41 -> 0 | AR34: =$M34*(1+$N34)*AD34*Assumpt!I$41 -> 0 | AS34: =SUM(AM34:AR34) -> 0 | AU34: =$M34*(1+$N34)*AE34*Assumpt!J$39 -> 0 | AV34: =$M34*(1+$N34)*AF34*Assumpt!K$39 -> 0 | AW34: =$M34*(1+$N34)*AG34*Assumpt!L$39 -> 0 | AX34: =$M34*(1+$N34)*AH34*Assumpt!M$39 -> 0 | AY34: =SUM(AU34:AX34) -> 0 | AZ34: =AL34+AS34+AY34 -> 0 | BC34: =AV34-AU34 -> 0
H35: =CONCATENATE(K35,I35) -> 11ODCS | I35: ODCS | J35: Contingency | K35: 11 | M35: 250000 | Y35: 0.75 | Z35: 1 | AA35: 1 | AB35: 1 | AC35: 1 | AD35: 1 | AE35: 1 | AF35: 1 | AG35: 1 | AH35: 1 | AN35: =$M35*(1+$N35)*Z35*Assumpt!E$41 -> 250000 | AO35: =$M35*(1+$N35)*AA35*Assumpt!F$41 -> 250000 | AP35: =$M35*(1+$N35)*AB35*Assumpt!G$41 -> 250000 | AQ35: =$M35*(1+$N35)*AC35*Assumpt!H$41 -> 250000 | AR35: =$M35*(1+$N35)*AD35*Assumpt!I$41 -> 250000 | AS35: =SUM(AM35:AR35) -> 1250000 | AU35: =$M35*(1+$N35)*AE35*Assumpt!J$39 -> 281377.2 | AV35: =$M35*(1+$N35)*AF35*Assumpt!K$39 -> 281377.2 | AW35: =$M35*(1+$N35)*AG35*Assumpt!L$39 -> 281377.2 | AX35: =$M35*(1+$N35)*AH35*Assumpt!M$39 -> 281377.2 | AY35: =SUM(AU35:AX35) -> 1125508.8 | AZ35: =AL35+AS35+AY35 -> 2375508.8 | BC35: =AV35-AU35 -> 0
A36: ODCS from Arden | H36: =CONCATENATE(K36,I36) | AS36: =SUM(AM36:AR36) -> 0 | AY36: =SUM(AU36:AX36) -> 0 | AZ36: =AL36+AS36+AY36 -> 0 | BC36: =AV36-AU36 -> 0
H37: =CONCATENATE(K37,I37) | AS37: =SUM(AM37:AR37) -> 0 | AY37: =SUM(AU37:AX37) -> 0 | AZ37: =AL37+AS37+AY37 -> 0 | BC37: =AV37-AU37 -> 0
H38: =CONCATENATE(K38,I38) | AS38: =SUM(AM38:AR38) -> 0 | AY38: =SUM(AU38:AX38) -> 0 | AZ38: =AL38+AS38+AY38 -> 0 | BC38: =AV38-AU38 -> 0
H39: =CONCATENATE(K39,I39) -> 11ODCS | I39: ODCS | J39: Depreciation | K39: 11 | AS39: =SUM(AM39:AR39) -> 0 | AU39: =AR39*Assumpt!$E$40 -> 0 | AV39: =AU39*Assumpt!$E$40 -> 0 | AW39: =AV39*Assumpt!$E$40 -> 0 | AX39: =AW39*Assumpt!$E$40 -> 0 | AY39: =SUM(AU39:AX39) -> 0 | AZ39: =AL39+AS39+AY39 -> 0 | BC39: =AV39-AU39 -> 0
H40: =CONCATENATE(K40,I40) -> 11ODCS | I40: ODCS | J40: Other Penalities | K40: 11 | AM40: 0 | AN40: 0 | AO40: =AN40*Assumpt!$E$40 -> 0 | AP40: =AO40*Assumpt!$E$40 -> 0 | AQ40: =AP40*Assumpt!$E$40 -> 0 | AR40: =AQ40*Assumpt!$E$40 -> 0 | AS40: =SUM(AM40:AR40) -> 0 | AU40: =AR40*Assumpt!$E$40 -> 0 | AV40: =AU40*Assumpt!$E$40 -> 0 | AW40: =AV40*Assumpt!$E$40 -> 0 | AX40: =AW40*Assumpt!$E$40 -> 0 | AY40: =SUM(AU40:AX40) -> 0 | AZ40: =AL40+AS40+AY40 -> 0 | BC40: =AV40-AU40 -> 0
H41: =CONCATENATE(K41,I41) -> 11ODCS | I41: ODCS | J41: Office Supplies - Construction | K41: 11 | AM41: 0 | AN41: 0 | AO41: =AN41*Assumpt!$E$40 -> 0 | AP41: =AO41*Assumpt!$E$40 -> 0 | AQ41: =AP41*Assumpt!$E$40 -> 0 | AR41: =AQ41*Assumpt!$E$40 -> 0 | AS41: =SUM(AM41:AR41) -> 0 | AU41: =AR41*Assumpt!$E$40 -> 0 | AV41: =AU41*Assumpt!$E$40 -> 0 | AW41: =AV41*Assumpt!$E$40 -> 0 | AX41: =AW41*Assumpt!$E$40 -> 0 | AY41: =SUM(AU41:AX41) -> 0 | AZ41: =AL41+AS41+AY41 -> 0 | BC41: =AV41-AU41 -> 0
H42: =CONCATENATE(K42,I42) -> 11ODCS | I42: ODCS | J42: MCI VID System | K42: 11 | AM42: 0 | AN42: 0 | AO42: =AN42*Assumpt!$E$40 -> 0 | AP42: =AO42*Assumpt!$E$40 -> 0 | AQ42: =AP42*Assumpt!$E$40 -> 0 | AR42: =AQ42*Assumpt!$E$40 -> 0 | AS42: =SUM(AM42:AR42) -> 0 | AU42: =AR42*Assumpt!$E$40 -> 0 | AV42: =AU42*Assumpt!$E$40 -> 0 | AW42: =AV42*Assumpt!$E$40 -> 0 | AX42: =AW42*Assumpt!$E$40 -> 0 | AY42: =SUM(AU42:AX42) -> 0 | AZ42: =AL42+AS42+AY42 -> 0 | BC42: =AV42-AU42 -> 0
...

Sheet cash flow
F2: startup | G2: Year 1 | H2: Year 2 | I2: Year 3 | J2: Year 4 | K2: Year 5 | L2: Year 6 | M2: Total Years 0 - 6 | V2: Year 7 costs | W2: Year 8 costs | X2: Year 9 costs | Y2: Year 10 costs | Z2: Total costs Years 7-10
A3: Summary
B4: Revenue | G4: =G21 -> 25400586 | H4: =H21 -> 32254194 | I4: =I21 -> 29991650 | J4: =J21 -> 30343573 | K4: =K21 -> 30741693 | L4: =L21 -> 30903854 | M4: =SUM(G4:L4) -> 1.7963555e+08 | V4: =V21 -> 31564253 | W4: =W21 -> 31266527 | X4: =X21 -> 31433602 | Y4: =Y21 -> 31986462 | Z4: =Z21 -> 1.2625084e+08 | AA4: =Z4+M4 -> 3.058864e+08
B5: Expenses | G5: =G34 -> 25165256 | H5: =H34 -> 28036995 | I5: =I34 -> 27830703 | J5: =J34 -> 28160631 | K5: =K34 -> 28533868 | L5: =L34 -> 28685895 | M5: =SUM(G5:L5) -> 1.6641335e+08 | V5: =V34 -> 29335018 | W5: =W34 -> 29055901 | X5: =X34 -> 29212534 | Y5: =Y34 -> 29730839 | Z5: =Z34 -> 1.1733429e+08 | AA5: =Z5+M5 -> 2.8374764e+08
B6: Profit | G6: =G4-G5 -> 235329.55 | H6: =H4-H5 -> 4217198.6 | I6: =I4-I5 -> 2160946.9 | J6: =J4-J5 -> 2182942.1 | K6: =K4-K5 -> 2207824.6 | L6: =L4-L5 -> 2217959.6 | M6: =SUM(G6:L6) -> 13222201 | O6: =M6-P150 -> 1.4901161e-08 | V6: =V4-V5 -> 2229234.6 | W6: =W4-W5 -> 2210626.7 | X6: =X4-X5 -> 2221068.9 | Y6: =Y4-Y5 -> 2255622.6 | Z6: =Z4-Z5 -> 8916552.8 | AA6: =AA4-AA5 -> 22138754 | AB6: =AC150-Z6 -> 0
B7: Cumulative profit | G7: =G6 -> 235329.55 | H7: =G7+H6 -> 4452528.2 | I7: =H7+I6 -> 6613475.1 | J7: =I7+J6 -> 8796417.1 | K7: =J7+K6 -> 11004242 | L7: =K7+L6 -> 13222201 | V7: =V6 -> 2229234.6 | W7: =V7+W6 -> 4439861.3 | X7: =W7+X6 -> 6660930.2 | Y7: =X7+Y6 -> 8916552.8 | AA7: =Z7 -> 0
L8: GP& | M8: =(M4-M5)/M5 -> 0.07945397 | Y8: GP& | Z8: =(Z4-Z5)/Z5 -> 0.075992727 | AA8: =(AA4-AA5)/AA5 -> 0.07802269
A11: Revenue totals
A12: 1 | B12: All NGVID Required Documents Bid Solicitation Section 3.51, 3.52 | G12: =G54 -> 81251.111 | M12: =SUM(G12:L12) -> 81251.111 | V12: =V59 -> 0 | W12: =W59 -> 0 | X12: =X59 -> 0 | Y12: =Y59 -> 0 | Z12: =SUM(V12:Y12) -> 0
A13: 2 | B13: Design, Development, and Implementation Bid Solicitation Section 3.38, 3.39.1 | G13: =G57 -> 323798.08 | M13: =SUM(G13:L13) -> 323798.08 | V13: =V60 -> 0 | W13: =W60 -> 0 | X13: =X60 -> 0 | Y13: =Y60 -> 0 | Z13: =SUM(V13:Y13) -> 0
A14: 3 | B14: PIF desktop | G14: =G61 -> 680833.33 | H14: =H61 -> 2042500 | M14: =SUM(G14:L14) -> 2723333.3 | V14: =V61 -> 0 | W14: =W61 -> 0 | X14: =X61 -> 0 | Y14: =Y61 -> 0 | Z14: =SUM(V14:Y14) -> 0
A15: 5 | B15: Inspection transaction fee for PIFs and PFFs (days 91 - 365, maintenance only)Bid Solicitation Section 3.1.3 & 3.27 | G15: =G66 -> 0 | M15: =SUM(G15:L15) -> 0 | Z15: =SUM(V15:Y15) -> 0
A16: 6 | B16: Inspection transaction fee for PIFs and PFFs (days 91 - 365, maintenance only)Bid Solicitation Section 3.1.3 & 3.27 | G16: =G72 -> 814810 | H16: =H72 -> 1282500 | I16: =I72 -> 1282500 | J16: =J72 -> 1282500 | K16: =K72 -> 1282500 | L16: =L72 -> 1282500 | M16: =SUM(G16:L16) -> 7227310 | V16: =V72 -> 1282500 | W16: =W72 -> 1282500 | X16: =X72 -> 1282500 | Y16: =Y72 -> 1282500 | Z16: =SUM(V16:Y16) -> 5130000
A17: 9 | B17: CIF Retrofit | G17: =O128 -> 1444985.5 | M17: =SUM(G17:L17) -> 1444985.5 | V17: =AC128 -> 0 | W17: =AD128 -> 0 | X17: =AE128 -> 0 | Y17: =AF128 -> 0 | Z17: =SUM(V17:Y17) -> 0
A18: 10 | B18: Revenue CIF | G18: =G82 -> 0 | M18: =SUM(G18:L18) -> 0 | Z18: =SUM(V18:Y18) -> 0
A19: 11 | B19: Revenue CIF | G19: =G147 -> 22054908 | H19: =H147 -> 28929194 | I19: =I147 -> 28709150 | J19: =J147 -> 29061073 | K19: =K147 -> 29459193 | L19: =L147 -> 29621354 | M19: =SUM(G19:L19) -> 1.6783487e+08 | V19: =V86 -> 30281753 | W19: =W86 -> 29984027 | X19: =X86 -> 30151102 | Y19: =Y86 -> 30703962 | Z19: =SUM(V19:Y19) -> 1.2112084e+08
M20: =SUM(G20:L20) -> 0 | Z20: =SUM(V20:Y20) -> 0
B21: Total | G21: =SUM(G12:G19) -> 25400586 | H21: =SUM(H12:H19) -> 32254194 | I21: =SUM(I12:I19) -> 29991650 | J21: =SUM(J12:J19) -> 30343573 | K21: =SUM(K12:K19) -> 30741693 | L21: =SUM(L12:L19) -> 30903854 | M21: =SUM(G21:L21) -> 1.7963555e+08 | N21: =M21-M87 -> 0 | V21: =SUM(V12:V19) -> 31564253 | W21: =SUM(W12:W19) -> 31266527 | X21: =SUM(X12:X19) -> 31433602 | Y21: =SUM(Y12:Y19) -> 31986462 | Z21: =SUM(V21:Y21) -> 1.2625084e+08
A23: Expense totals
A24: 1 | B24: All NGVID Required Documents Bid Solicitation Section 3.51, 3.52 | G24: =G93 -> 73125 | H24: =H93 -> 1 | I24: =I93 -> 0 | J24: =J93 -> 0 | K24: =K93 -> 0 | L24: =L93 -> 0 | M24: =SUM(G24:L24) -> 73126 | V24: =V93 -> 0 | W24: =W93 -> 0 | X24: =X93 -> 0 | Y24: =Y93 -> 0 | Z24: =SUM(V24:Y24) -> 0
A25: 2 | B25: Design, Development, and Implementation Bid Solicitation Section 3.38, 3.39.1 | G25: =G98 -> 291418.27 | H25: =H98 -> 0 | I25: =I98 -> 0 | J25: =J98 -> 0 | K25: =K98 -> 0 | L25: =L98 -> 0 | M25: =SUM(G25:L25) -> 291418.27 | V25: =V98 -> 0 | W25: =W98 -> 0 | X25: =X98 -> 0 | Y25: =Y98 -> 0 | Z25: =SUM(V25:Y25) -> 0
A26: 3 | B26: PIF desktop | G26: =G104 -> 2042500 | H26: =H104 -> 0 | I26: =I104 -> 0 | J26: =J104 -> 0 | K26: =K104 -> 0 | L26: =L104 -> 0 | M26: =SUM(G26:L26) -> 2042500 | V26: =V104 -> 0 | W26: =W104 -> 0 | X26: =X104 -> 0 | Y26: =Y104 -> 0 | Z26: =SUM(V26:Y26) -> 0
M27: =SUM(G27:L27) -> 0 | Z27: =SUM(V27:Y27) -> 0
A28: 5 | B28: Inspection transaction fee for PIFs and PFFs (days 91 - 365, maintenance only)Bid Solicitation Section 3.1.3 & 3.27 | G28: =G109 -> 0 | M28: =SUM(G28:L28) -> 0 | V28: =V109 -> 0 | W28: =W109 -> 0 | X28: =X109 -> 0 | Y28: =Y109 -> 0 | Z28: =SUM(V28:Y28) -> 0
A29: 6 | B29: Inspection transaction fee for PIFs and PFFs (including NGVID & all maintenance) Bid Solicitation Section 3.1.2 | H29: =H117 -> 134625 | I29: =I117 -> 134625 | J29: =J117 -> 134625 | K29: =K117 -> 134625 | L29: =L117 -> 134625 | M29: =SUM(G29:L29) -> 673125 | V29: =V117 -> 164625 | W29: =W117 -> 164625 | X29: =X117 -> 164625 | Y29: =Y117 -> 164625 | Z29: =SUM(V29:Y29) -> 658500
A30: 9 | B30: CIF Retrofit | G30: =G128 -> 1300486.9 | H30: =H128 -> 0 | I30: =I128 -> 0 | J30: =J128 -> 0 | K30: =K128 -> 0 | L30: =L128 -> 0 | M30: =SUM(G30:L30) -> 1300486.9 | V30: =V128 -> 0 | W30: =W128 -> 0 | X30: =X128 -> 0 | Y30: =Y128 -> 0 | Z30: =SUM(V30:Y30) -> 0
A31: 10 | B31: Revenue CIF | G31: =G134 -> 0 | M31: =SUM(G31:L31) -> 0 | V31: =V134 -> 0 | W31: =W134 -> 0 | X31: =X134 -> 0 | Y31: =Y134 -> 0 | Z31: =SUM(V31:Y31) -> 0
A32: 11 | B32: Revenue CIF | G32: =G141 -> 21457726 | H32: =H141 -> 27902369 | I32: =I141 -> 27696078 | J32: =J141 -> 28026006 | K32: =K141 -> 28399243 | L32: =L141 -> 28551270 | M32: =SUM(G32:L32) -> 1.6203269e+08 | V32: =V141 -> 29170393 | W32: =W141 -> 28891276 | X32: =X141 -> 29047909 | Y32: =Y141 -> 29566214 | Z32: =SUM(V32:Y32) -> 1.1667579e+08
Z33: =SUM(V33:Y33) -> 0
B34: Total | G34: =SUM(G24:G32) -> 25165256 | H34: =SUM(H24:H32) -> 28036995 | I34: =SUM(I24:I32) -> 27830703 | J34: =SUM(J24:J32) -> 28160631 | K34: =SUM(K24:K32) -> 28533868 | L34: =SUM(L24:L32) -> 28685895 | M34: =SUM(G34:L34) -> 1.6641335e+08 | V34: =SUM(V24:V32) -> 29335018 | W34: =SUM(W24:W32) -> 29055901 | X34: =SUM(X24:X32) -> 29212534 | Y34: =SUM(Y24:Y32) -> 29730839 | Z34: =SUM(V34:Y34) -> 1.1733429e+08
F36: xcheck | G36: ='Pricing details'!AM139-G34 -> 0 | H36: ='Pricing details'!AN139-H34 -> 0 | I36: ='Pricing details'!AO139-I34 -> 0 | J36: ='Pricing details'!AP139-J34 -> 0 | K36: ='Pricing details'!AQ139-K34 -> 0 | L36: ='Pricing details'!AR139-L34 -> 0 | M36: ='Pricing details'!AS139-M34 -> 0 | V36: ='Pricing details'!AU122-'cash flow'!V34 -> 0 | W36: ='Pricing details'!AV122-'cash flow'!W34 -> 0 | X36: ='Pricing details'!AW122-'cash flow'!X34 -> 0 | Y36: ='Pricing details'!AX122-'cash flow'!Y34 -> 0 | Z36: =SUM(V36:Y36) -> 0
A37: Profit totals
A38: 1 | B38: All NGVID Required Documents Bid Solicitation Section 3.51, 3.52 | G38: =G12-G24 -> 8126.1111 | H38: =H12-H24 -> -1 | I38: =I12-I24 -> 0 | J38: =J12-J24 -> 0 | K38: =K12-K24 -> 0 | L38: =L12-L24 -> 0 | M38: =SUM(G38:L38) -> 8125.1111 | V38: =V12-V24 -> 0 | W38: =W12-W24 -> 0 | X38: =X12-X24 -> 0 | Y38: =Y12-Y24 -> 0 | Z38: =SUM(T38:Y38) -> 0
A39: 2 | B39: Design, Development, and Implementation Bid Solicitation Section 3.38, 3.39.1 | G39: =G13-G25 -> 32379.808 | H39: =H13-H25 -> 0 | I39: =I13-I25 -> 0 | J39: =J13-J25 -> 0 | K39: =K13-K25 -> 0 | L39: =L13-L25 -> 0 | M39: =SUM(G39:L39) -> 32379.808 | V39: =V13-V25 -> 0 | W39: =W13-W25 -> 0 | X39: =X13-X25 -> 0 | Y39: =Y13-Y25 -> 0 | Z39: =SUM(T39:Y39) -> 0
A40: 3 | B40: PIF desktop | G40: =G14-G26 -> -1361666.7 | H40: =H14-H26 -> 2042500 | I40: =I14-I26 -> 0 | J40: =J14-J26 -> 0 | K40: =K14-K26 -> 0 | L40: =L14-L26 -> 0 | M40: =SUM(G40:L40) -> 680833.33 | V40: =V14-V26 -> 0 | W40: =W14-W26 -> 0 | X40: =X14-X26 -> 0 | Y40: =Y14-Y26 -> 0 | Z40: =SUM(T40:Y40) -> 0
A41: 5 | B41: Inspection transaction fee for PIFs and PFFs (days 91 - 365, maintenance only)Bid Solicitation Section 3.1.3 & 3.27 | G41: =G15-G28 -> 0 | M41: =SUM(G41:L41) -> 0 | Z41: =SUM(T41:Y41) -> 0
A42: 6 | B42: Inspection transaction fee for PIFs and PFFs (including NGVID & all maintenance) Bid Solicitation Section 3.1.2 | G42: =G16-G29 -> 814810 | H42: =H16-H29 -> 1147875 | I42: =I16-I29 -> 1147875 | J42: =J16-J29 -> 1147875 | K42: =K16-K29 -> 1147875 | L42: =L16-L29 -> 1147875 | M42: =SUM(G42:L42) -> 6554185 | O42: =M42-P119 -> 0 | V42: =V16-V29 -> 1117875 | W42: =W16-W29 -> 1117875 | X42: =X16-X29 -> 1117875 | Y42: =Y16-Y29 -> 1117875 | Z42: =SUM(T42:Y42) -> 4471500
A43: 9 | B43: CIF Retrofit | G43: =(G17-G30)+(H17-H30) -> 144498.55 | I43: =I17-I30 -> 0 | J43: =J17-J30 -> 0 | K43: =K17-K30 -> 0 | L43: =L17-L30 -> 0 | M43: =SUM(G43:L43) -> 144498.55 | V43: =V17-V30 -> 0 | W43: =W17-W30 -> 0 | X43: =X17-X30 -> 0 | Y43: =Y17-Y30 -> 0 | Z43: =SUM(T43:Y43) -> 0
A44: 10 | B44: Revenue CIF | G44: =G18-G31 -> 0 | M44: =SUM(G44:L44) -> 0 | Z44: =SUM(T44:Y44) -> 0
A45: 11 | B45: Revenue CIF | G45: =G19-G32 -> 597181.75 | H45: =H19-H32 -> 1026824.6 | I45: =I19-I32 -> 1013071.9 | J45: =J19-J32 -> 1035067.1 | K45: =K19-K32 -> 1059949.6 | L45: =L19-L32 -> 1070084.6 | M45: =SUM(G45:L45) -> 5802179.5 | V45: =V19-V32 -> 1111359.6 | W45: =W19-W32 -> 1092751.7 | X45: =X19-X32 -> 1103193.9 | Y45: =Y19-Y32 -> 1137747.6 | Z45: =SUM(T45:Y45) -> 4445052.8
...

Sheet price submittal form
A1: State-Supplied Price Sheet Bid Solicitation # 20DPP00471 T1628 - Enhanced Motor Vehicle Inspection Maintenance System
A2: Vendor {Bidder} Name:
A3: Instructions: | E3: Refer to Bid Solicitation Section 4.4.5 for Vendor {Bidder} instruction. The Vendor {Bidder} shall provide pricing for all of the yellow highlighted cells including the optional extension cells.
A4: Description/Service | C4: Estimated Volume Per Year | D4: Unit of Measurement | E4: Year 1 All-Inclusive Price | F4: Year 2 All-Inclusive Price | G4: Year 3 All-Inclusive Price | H4: Year 4 All-Inclusive Price | I4: Year 5 All-Inclusive Price | J4: Year 6 All-Inclusive Price | K4: Total Cost | L4: Year 7 All-Inclusive Price (Optional Extension - See Section 5.2) | M4: Year 8 All-Inclusive Price (Optional Extension - See Section 5.2) | N4: Year 9 All-Inclusive Price (Optional Extension - See Section 5.2) | O4: Year 10 All-Inclusive Price (Optional Extension - See Section 5.2)
A5: VID DEVELOPMENT - NEXT GENERATION VEHICLE INSPECTION SYSTEM | T5: Cross check
A6: 1 | B6: All NGVID Required Documents Bid Solicitation Section 3.51, 3.52 | C6: 1 | D6: TASK | K6: ='cash flow'!O93 -> 81251.111 | T6: ='cash flow'!M54 -> 81251.111 | U6: =K6-T6 -> 0
A7: 2 | B7: Design, Development, and Implementation Bid Solicitation Section 3.38, 3.39.1 | C7: 1 | D7: TASK | K7: ='cash flow'!O98 -> 323798.08 | T7: ='cash flow'!M57 -> 323798.08 | U7: =K7-T7 -> 0
A8: PIFs AND PFFs
A9: 3 | B9: NGWorkstation price to PIFs and PFFs (PC based - PC, monitor, barcode reader, printer, scan tool, keyboard, mouse) Bid Solicitation Section 3.26, 3.27, 3.28 | C9: 1250 | D9: EACH | F9: ='cash flow'!O104 -> 2178.6667 | K9: =SUM(F9:J9)*C9 -> 2723333.3 | T9: ='cash flow'!M61 -> 2723333.3 | U9: =K9-T9 -> 0
A10: 4 | B10: NGWorkstation price to PIFs and PFFs (Tablet based - Tablet, printer, scan tool) Bid Solicitation Section 3.26, 3.27, 3.28 | C10: 1250 | D10: EACH | F10: 0 | K10: =SUM(F10:J10)*C10 -> 0
A11: 5 | B11: Inspection transaction fee for PIFs and PFFs (days 91 - 365, maintenance only) Bid Solicitation Section 3.1.3 & 3.27 | C11: 205000 | D11: EACH | E11: ='cash flow'!G120 -> 3.9746829 | K11: =SUM(E11)*C11 -> 814810 | T11: ='cash flow'!G72 -> 814810 | U11: =K11-T11 -> 0
A12: 6 | B12: Inspection transaction fee for PIFs and PFFs (including NGVID & all maintenance) Bid Solicitation Section 3.1.2 | C12: 255000 | D12: EACH | F12: ='cash flow'!$H$120 -> 5.0294118 | G12: =F12 -> 5.0294118 | H12: =G12 -> 5.0294118 | I12: =H12 -> 5.0294118 | J12: =I12 -> 5.0294118 | K12: =SUM(F12:J12)*C12 -> 6412500 | L12: =J12 -> 5.0294118 | M12: =L12 -> 5.0294118 | N12: =L12 -> 5.0294118 | O12: =M12 -> 5.0294118 | T12: =SUM('cash flow'!H72:L72) -> 6412500 | U12: =K12-T12 -> 0
A13: 7 | B13: NGWorkstation price to PIFs and PFFs (Laptop based - Laptop, printer, barcode reader, scan tool) Bid Solicitation Section 3.26, 3.27, 3.28 | C13: 1250 | D13: EACH | K13: =SUM(F13:J13)*C13 -> 0
A14: CIFS - STARTUP, RETROFIT, IMPROVEMENT, AND PER INSPECTION COST
A15: 8 | B15: Training State Staff on NGSystem (Price Per Employee) Bid Solicitation Section 3.48 | C15: 150 | D15: EACH | E15: 0 | F15: 0 | G15: 0 | H15: 0 | I15: 0 | J15: 0 | L15: 0 | M15: 0 | N15: 0 | O15: 0
A16: 9 | B16: CIF Retrofit - Removal of old equipment, installation of new equipment (NGWorkstations), facility acceptance testing. Bid Solicitation Section 3.13.5 | C16: 125 | D16: EACH | E16: ='cash flow'!O129 -> 11559.884 | F16: 0 | G16: 0 | H16: 0 | I16: 0 | J16: 0 | K16: =SUM(E16:J16)*C16 -> 1444985.5 | L16: 0 | M16: 0 | N16: 0 | O16: 0 | T16: ='cash flow'!M76 -> 1444985.5 | U16: =K16-T16 -> 0
A17: 10 | B17: Cost per inspection at CIFs. Includes all CIF operational costs (days 91 - 365 [excluding the Legacy VID transaction cost]) - Inclusive of all State operational costs Bid Solicitation Section 3.1.3, 3.2.1 | C17: 1425000 | D17: EACH | E17: ='cash flow'!G85 -> 15.477128 | K17: =SUM(E17)*C17 -> 22054908 | T17: ='cash flow'!G86 -> 22054908 | U17: =K17-T17 -> 0
A18: 11 | B18: Cost per inspection at CIFs (Includes all CIF operational costs.) - Inclusive of all State operational costs Bid Solicitation Section 3.1.2 | C18: 1900000 | D18: EACH | F18: ='cash flow'!H85 -> 15.225892 | G18: ='cash flow'!I148 -> 15.110079 | H18: ='cash flow'!J148 -> 15.295302 | I18: ='cash flow'!K148 -> 15.504838 | J18: ='cash flow'!L148 -> 15.590186 | K18: =SUM(F18:J18)*C18 -> 1.4577996e+08 | L18: ='cash flow'!V85 -> 15.937765 | M18: ='cash flow'!W85 -> 15.781067 | N18: ='cash flow'!X85 -> 15.869001 | O18: ='cash flow'!Y85 -> 16.15998 | T18: =SUM('cash flow'!H86:L86) -> 1.4577996e+08 | U18: =K18-T18 -> 0
A19: Total Cost | K19: =SUM(K6:K18) -> 1.7963555e+08 | R19: Totaal cost of prgram without PIF/PFF | S19: =K6 -> 81251.111 | T19: =SUM(T6:T18) -> 1.7963555e+08 | U19: =K19-T19 -> 0
A20: MISCELLANEOUS HOURLY RATES PURSUANT TO SECTIONS 3.13.2.2, 3.14.1, 3.47 and 5.16 - review sections here and in cells below | R20: Total cost from P&L
A21: 12 | B21: Additional Work Bid Solicitation Section 3.13.2.2 | C21: 1 | D21: HOUR | R21: delta | S21: =S19-S20 -> 81251.111
A22: 13 | B22: Project Manager Bid Solicitation Section 3.14.1 | C22: 1 | D22: HOUR | E22: 121.524 | F22: 122.73924 | G22: 123.96664 | H22: 125.2063 | I22: 126.45836 | J22: 127.72295 | L22: 129.00018 | M22: 130.29018 | N22: 131.59308 | O22: 132.90901
A23: 14 | B23: Business Analyst Bid Solicitation Section 3.14.1 | C23: 1 | D23: HOUR | E23: 81.541885 | F23: 82.357304 | G23: 83.180877 | H23: 84.012685 | I23: 84.852812 | J23: 85.70134 | L23: 86.558354 | M23: 87.423937 | N23: 88.298177 | O23: 89.181158
A24: 15 | B24: User Interface Designer Bid Solicitation Section 3.14.1 | C24: 1 | D24: HOUR | E24: 119.59476 | F24: 120.79071 | G24: 121.99862 | H24: 123.21861 | I24: 124.45079 | J24: 125.6953 | L24: 126.95225 | M24: 128.22177 | N24: 129.50399 | O24: 130.79903
A25: 16 | B25: Developer Bid Solicitation Section 3.14.1 | C25: 1 | D25: HOUR | E25: 89.152461 | F25: 90.043985 | G25: 90.944425 | H25: 91.853869 | I25: 92.772408 | J25: 93.700132 | L25: 94.637133 | M25: 95.583505 | N25: 96.53934 | O25: 97.504733
A26: 17 | B26: Database Administrator Bid Solicitation Section 3.14.1 | C26: 1 | D26: HOUR | E26: 108.72251 | F26: 109.80974 | G26: 110.90784 | H26: 112.01691 | I26: 113.13708 | J26: 114.26845 | L26: 115.41114 | M26: 116.56525 | N26: 117.7309 | O26: 118.90821
A27: 18 | B27: Security Design Lead Bid Solicitation Section 3.14.1 | C27: 1 | D27: HOUR | E27: 192.0275 | F27: 193.94778 | G27: 195.88725 | H27: 197.84613 | I27: 199.82459 | J27: 201.82283 | L27: 203.84106 | M27: 205.87947 | N27: 207.93827 | O27: 210.01765
A28: 19 | B28: Security Tester Bid Solicitation Section 3.14.1 | C28: 1 | D28: HOUR | E28: 192.02235 | F28: 193.94257 | G28: 195.882 | H28: 197.84082 | I28: 199.81923 | J28: 201.81742 | L28: 203.83559 | M28: 205.87395 | N28: 207.93269 | O28: 210.01201
A29: 20 | B29: Quality Assurance Manager Bid Solicitation Section 3.14.1 | C29: 1 | D29: HOUR | E29: 81.541885 | F29: 82.357304 | G29: 83.180877 | H29: 84.012685 | I29: 84.852812 | J29: 85.70134 | L29: 86.558354 | M29: 87.423937 | N29: 88.298177 | O29: 89.181158
A30: PIF/PFF REPLACEMENT EQUIPMENT
A31: 21 | B31: Monitor Bid Solicitation Section 3.26, 3.27, 3.28 | C31: 1 | D31: UNIT
A32: 22 | B32: Keyboard Bid Solicitation Section 3.26, 3.27, 3.28 | C32: 1 | D32: UNIT
A33: 23 | B33: Mouse Bid Solicitation Section 3.26, 3.27, 3.28 | C33: 1 | D33: UNIT
A34: 24 | B34: OBD Scan Tool Bid Solicitation Section 3.26, 3.27, 3.28 | C34: 1 | D34: UNIT
A35: 25 | B35: Bar Code Scanner Bid Solicitation Section 3.26, 3.27, 3.28 | C35: 1 | D35: UNIT
A36: 26 | B36: Printer Bid Solicitation Section 3.26, 3.27, 3.28 | C36: 1 | D36: UNIT
A37: 27 | B37: Tablet Bid Solicitation Section 3.26, 3.27, 3.28 | C37: 1 | D37: UNIT
A38: 28 | B38: Computer Bid Solicitation Section 3.26, 3.27, 3.28 | C38: 1 | D38: UNIT
A39: 29 | B39: Laptop Bid Solicitation Section 3.26, 3.27, 3.28 | C39: 1 | D39: UNIT
A40: 30 | B40: Other Bid Solicitation Section 3.26, 3.27, 3.28 | C40: 1 | D40: UNIT

Sheet Application Development
A1: rate | B1: =120000/2080 -> 57.692308 | E1: Requirements | F1: Implementation | G1: Hours | H1: check | J1: Notes
A2: Fringe | B2: 1.3 | C2: =100000/2080 -> 48.076923
A3: US exchange | B3: 0.75 | C3: =C2*0.8 -> 38.461538 | E3: 0.2 | F3: 0.8
A4: US $ | B4: =B1*B2*B3 -> 56.25 | C4: =B4/0.13 -> 432.69231
A5: Misc Applications | B5: =B4/1.3 -> 43.269231 | C5: Price line
A7: Billing Application | C7: 1 | D7: =$B$4*E7 -> 1687.5 | E7: =$E$3*G7 -> 30 | G7: 150 | H7: =$B$4*G7 -> 8437.5
C8: 2 | D8: =$B$4*F8 -> 6750 | F8: =$F$3*G7 -> 120
A10: Sticker Management (reporting) | C10: 1 | D10: =$B$4*E10 -> 1125 | E10: =$E$3*G10 -> 20 | G10: 100 | H10: =$B$4*G10 -> 5625
C11: 2 | D11: =$B$4*F11 -> 4500 | F11: =$F$3*G10 -> 80
A12: Public Websites
A13: School Bus Report Card | C13: 1 | D13: =$B$4*E13 -> 1125 | E13: =$E$3*G13 -> 20 | G13: 100 | H13: =$B$4*G13 -> 5625
C14: 2 | D14: =$B$4*F14 -> 4500 | F14: =$F$3*G13 -> 80
A16: VIR Reprint | C16: 1 | D16: =$B$4*E16 -> 1125 | E16: =$E$3*G16 -> 20 | G16: 100 | H16: =$B$4*G16 -> 5625
C17: 2 | D17: =$B$4*F17 -> 4500 | F17: =$F$3*G16 -> 80
A19: Wait Queue Cameras | C19: 1 | D19: =$B$4*E19 -> 1125 | E19: =$E$3*G19 -> 20 | G19: 100 | H19: =$B$4*G19 -> 5625
C20: 2 | D20: =$B$4*F20 -> 4500 | F20: =$F$3*G19 -> 80
A21: Administration Applications
A23: Facility Admin | C23: 1 | D23: =$B$4*E23 -> 1125 | E23: =$E$3*G23 -> 20 | G23: 100 | H23: =$B$4*G23 -> 5625
C24: 2 | D24: =$B$4*F24 -> 4500 | F24: =$F$3*G23 -> 80
A25: View Facility
A26: Manage Private Facility
A27: Update Facility
A28: Activate Facility
A29: Assign/Unassign Inspector
A30: Manage Centralized Facility
A31: Manage State Facility
A33: Inspector Admin | C33: 1 | D33: =$B$4*E33 -> 1125 | E33: =$E$3*G33 -> 20 | G33: 100 | H33: =$B$4*G33 -> 5625
C34: 2 | D34: =$B$4*F34 -> 4500 | F34: =$F$3*G33 -> 80
A35: View Auditor/Inspector | C35: 2
A36: Manage Inspector
A37: Manage Auditor
A38: Assign/Unassign PIF Inspector
A40: Vehicle Admin | C40: 1 | D40: =$B$4*E40 -> 1125 | E40: =$E$3*G40 -> 20 | G40: 100 | H40: =$B$4*G40 -> 5625
C41: 2 | D41: =$B$4*F41 -> 4500 | F41: =$F$3*G40 -> 80
A42: Manage Covert Vehicle
A43: Active Covert Vehicles
A44: Covert Vehicle History
A45: Manage Collector Vehicle
A47: Workstation Admin | C47: 1 | D47: =$B$4*E47 -> 1125 | E47: =$E$3*G47 -> 20 | G47: 100 | H47: =$B$4*G47 -> 5625
C48: 2 | D48: =$B$4*F48 -> 4500 | F48: =$F$3*G47 -> 80
...

Sheet infrastructureold
B1: Item | D1: Description | E1: Vendor | F1: Cost Split | J1: One-Time | N1: Recurring (Annual)
A2: Pickup | B2: RFP BUDGET IT Infrastructure Cost Model | Q2: Assumptions/Notes: Prices is US Dollars Taxes not included Recurring costs start from first year, unless specified Assume hardware refresh at year 5, 50% of initial cost
A4: x | B4: Item | D4: Description | E4: Vendor | F4: PA | G4: NJ | H4: VT | I4: MASS | J4: One-Time | N4: Recurring (Annual) | R4: Year 0 | S4: Year 1 | T4: Year 2 | U4: Year 3 | V4: Year 4 | W4: Year 5 | X4: Refresh Year 5 | Y4: Year 6 | Z4: Year 7 | AA4: Year 8 | AB4: Year 9 | AC4: Total
A5: =IF(W5>0,"x","") -> x | B5: Hosting | D5: Additional cabinet | E5: Verizon | G5: 1 | J5: 1 | K5: 5000 | L5: =J5*K5 -> 5000 | N5: =J5 -> 1 | O5: =2656*12*N5 -> 31872 | P5: =O5*N5 -> 31872 | R5: =L5+P5 -> 36872 | S5: =P5 -> 31872 | T5: =S5 -> 31872 | U5: =T5 -> 31872 | V5: =U5 -> 31872 | W5: =V5 -> 31872 | X5: =IF(C5="R",L5,) -> 0 | Y5: =V5 -> 31872 | Z5: =W5 -> 31872 | AA5: =Z5 -> 31872 | AB5: =AA5 -> 31872 | AC5: =SUM(R5:AB5) -> 323720
A6: =IF(W6>0,"x","") | B6: Cables / Wiring / Cable Management | E6: TBD | G6: 1 | J6: 1 | K6: 2000 | L6: =J6*K6 -> 2000 | N6: 1 | P6: =O6*N6 -> 0 | R6: =L6+P6 -> 2000 | S6: =P6 -> 0 | T6: =S6 -> 0 | U6: =T6 -> 0 | V6: =U6 -> 0 | W6: =V6 -> 0 | X6: =IF(C6="R",L6,) -> 0 | Y6: =V6 -> 0 | Z6: =W6 -> 0 | AA6: =Z6 -> 0 | AB6: =AA6 -> 0 | AC6: =SUM(R6:AB6) -> 2000
A7: =IF(W7>0,"x","") -> x | B7: VMware vSphere(Virtualization Hardware) | C7: R | D7: 2 x Intel® Xeon® E5-2699 v3 18-core 2.3GHz core Intel CPU, 512GB RAM, PROD | E7: HP | G7: 1 | J7: 2 | K7: 24000 | L7: =J7*K7 -> 48000 | M7: Default discount applied | N7: =J7 -> 2 | O7: =21%*K7 -> 5040 | P7: =O7*N7 -> 10080 | Q7: First year support paid at the time of purchase. Assume 50% increase for the last 2 yrs | R7: =L7+P7 -> 58080 | S7: =P7 -> 10080 | T7: =S7 -> 10080 | U7: =T7 -> 10080 | V7: =U7 -> 10080 | W7: =V7 -> 10080 | X7: =IF(C7="R",L7,) -> 48000 | Y7: =V7 -> 10080 | Z7: =W7 -> 10080 | AA7: =Z7 -> 10080 | AB7: =AA7 -> 10080 | AC7: =SUM(R7:AB7) -> 196800
A8: =IF(W8>0,"x","") -> x | B8: DB/HSM Server Refresh | D8: Oracle, T7-1, single socket 32-core SPARC CPU. System virtualized with LDOM, DB PROD, HSM PROD, all two node clusters | E8: Oracle | G8: 0.5 | I8: 0.5 | J8: 2 | K8: 40000 | L8: =J8*K8 -> 80000 | M8: Default discount applied | N8: =J8 -> 2 | O8: =15%*K8 -> 6000 | P8: =O8*N8 -> 12000 | Q8: First year support paid at the time of purchase. Assume 50% increase for the last 2 yrs | R8: =L8+P8 -> 92000 | S8: =P8 -> 12000 | T8: =S8 -> 12000 | U8: =T8 -> 12000 | V8: =U8 -> 12000 | W8: =V8 -> 12000 | X8: =IF(C8="R",L8,) -> 0 | Y8: =V8 -> 12000 | Z8: =W8 -> 12000 | AA8: =Z8 -> 12000 | AB8: =AA8 -> 12000 | AC8: =SUM(R8:AB8) -> 200000
A9: =IF(W9>0,"x","") -> x | B9: vCentre | C9: R | D9: HP DL360 G9 | E9: HP | G9: 1 | J9: 1 | K9: 8000 | L9: =J9*K9 -> 8000 | M9: Default discount applied | N9: =J9 -> 1 | O9: =21%*K9 -> 1680 | P9: =O9*N9 -> 1680 | Q9: First year support paid at the time of purchase. Assume 50% increase for the last 2 yrs | R9: =L9+P9 -> 9680 | S9: =P9 -> 1680 | T9: =S9 -> 1680 | U9: =T9 -> 1680 | V9: =U9 -> 1680 | W9: =V9 -> 1680 | X9: =IF(C9="R",L9,) -> 8000 | Y9: =V9 -> 1680 | Z9: =W9 -> 1680 | AA9: =Z9 -> 1680 | AB9: =AA9 -> 1680 | AC9: =SUM(R9:AB9) -> 32800
A10: =IF(W10>0,"x","") | B10: Centralized Logging/Network monitor/HIDS (virtualized) | D10: HP DL360 G9 | E10: HP | G10: 1 | J10: 0 | K10: 8000 | L10: =J10*K10 -> 0 | M10: Default discount applied | N10: =J10 -> 0 | O10: =21%*K10 -> 1680 | P10: =O10*N10 -> 0 | Q10: First year support paid at the time of purchase. Assume 50% increase for the last 2 yrs | R10: =L10+P10 -> 0 | S10: =P10 -> 0 | T10: =S10 -> 0 | U10: =T10 -> 0 | V10: =U10 -> 0 | W10: =V10 -> 0 | X10: =IF(C10="R",L10,) -> 0 | Y10: =V10 -> 0 | Z10: =W10 -> 0 | AA10: =Z10 -> 0 | AB10: =AA10 -> 0 | AC10: =SUM(R10:AB10) -> 0
A11: =IF(W11>0,"x","") -> x | B11: VMware storage - Oracle ZFS 3-2 | C11: R | D11: Storage Equipment for Vsphere environment | E11: Oracle | G11: 1 | J11: 1 | K11: 65000 | L11: =J11*K11 -> 65000 | M11: Default discount applied | N11: =J11 -> 1 | O11: =21%*K11 -> 13650 | P11: =O11*N11 -> 13650 | Q11: First year support paid at the time of purchase. Assume 50% increase for the last 2 yrs | R11: =L11+P11 -> 78650 | S11: =P11 -> 13650 | T11: =S11 -> 13650 | U11: =T11 -> 13650 | V11: =U11 -> 13650 | W11: =V11 -> 13650 | X11: =IF(C11="R",L11,) -> 65000 | Y11: =V11 -> 13650 | Z11: =W11 -> 13650 | AA11: =Z11 -> 13650 | AB11: =AA11 -> 13650 | AC11: =SUM(R11:AB11) -> 266500
A12: =IF(W12>0,"x","") | B12: Backup server (consolidated on the SPARC system) | D12: HP DL360 G9 | E12: HP | G12: 1 | J12: 0 | K12: 8000 | L12: =J12*K12 -> 0 | M12: Default discount applied | N12: =J12 -> 0 | O12: =21%*K12 -> 1680 | P12: =O12*N12 -> 0 | Q12: First year support paid at the time of purchase. Assume 50% increase for the last 2 yrs | R12: =L12+P12 -> 0 | S12: =P12 -> 0 | T12: =S12 -> 0 | U12: =T12 -> 0 | V12: =U12 -> 0 | W12: =V12 -> 0 | X12: =IF(C12="R",L12,) -> 0 | Y12: =V12 -> 0 | Z12: =W12 -> 0 | AA12: =Z12 -> 0 | AB12: =AA12 -> 0 | AC12: =SUM(R12:AB12) -> 0
A13: =IF(W13>0,"x","") -> x | B13: DB/HSM Server Refresh | D13: Oracle, T7-1, single socket 32-core SPARC CPU. System virtualized with LDOM, DB DTS, HSM DTS, all two node clusters | E13: Oracle | G13: 0.5 | I13: 0.5 | J13: 2 | K13: 44000 | L13: =J13*K13 -> 88000 | M13: Default discount applied | N13: =J13 -> 2 | O13: =16%*K13 -> 7040 | P13: =O13*N13 -> 14080 | Q13: First year support paid at the time of purchase. Assume 50% increase for the last 2 yrs | R13: =L13+P13 -> 102080 | S13: =P13 -> 14080 | T13: =S13 -> 14080 | U13: =T13 -> 14080 | V13: =U13 -> 14080 | W13: =V13 -> 14080 | X13: =IF(C13="R",L13,) -> 0 | Y13: =V13 -> 14080 | Z13: =W13 -> 14080 | AA13: =Z13 -> 14080 | AB13: =AA13 -> 14080 | AC13: =SUM(R13:AB13) -> 228800
A14: =IF(W14>0,"x","") -> x | B14: Switch - 10GB | C14: R | D14: Cisco 10GB Switch - assumed 40% discount | E14: Cisco | G14: 1 | J14: 4 | K14: 20400 | L14: =J14*K14 -> 81600 | M14: 40% discount | N14: =J14 -> 4 | O14: =21%*K14 -> 4284 | P14: =O14*N14 -> 17136 | Q14: First year support paid at the time of purchase. Assume 50% increase for the last 2 yrs | R14: =L14+P14 -> 98736 | S14: =P14 -> 17136 | T14: =S14 -> 17136 | U14: =T14 -> 17136 | V14: =U14 -> 17136 | W14: =V14 -> 17136 | X14: =IF(C14="R",L14,) -> 81600 | Y14: =V14 -> 17136 | Z14: =W14 -> 17136 | AA14: =Z14 -> 17136 | AB14: =AA14 -> 17136 | AC14: =SUM(R14:AB14) -> 334560
A15: =IF(W15>0,"x","") -> x | B15: Centralized Stations VPN hardware | D15: cisco 1841 | E15: Cisco | G15: 1 | J15: 36 | K15: 1200 | L15: =J15*K15 -> 43200 | N15: =J15 -> 36 | O15: =21%*K15 -> 252 | P15: =O15*N15 -> 9072 | Q15: First year support paid at the time of purchase. Assume 50% increase for the last 2 yrs | R15: =L15+P15 -> 52272 | S15: =P15 -> 9072 | T15: =S15 -> 9072 | U15: =T15 -> 9072 | V15: =U15 -> 9072 | W15: =V15 -> 9072 | X15: =IF(C15="R",L15,) -> 0 | Y15: =V15 -> 9072 | Z15: =W15 -> 9072 | AA15: =Z15 -> 9072 | AB15: =AA15 -> 9072 | AC15: =SUM(R15:AB15) -> 133920
A16: =IF(W16>0,"x","") -> x | B16: Firewall / IPS | C16: R | D16: assumed 40% discount | E16: Cisco | G16: 1 | J16: 2 | K16: 17000 | L16: =J16*K16 -> 34000 | M16: 40% discount | N16: =J16 -> 2 | O16: =21%*K16 -> 3570 | P16: =O16*N16 -> 7140 | Q16: First year support paid at the time of purchase. Assume 50% increase for the last 2 yrs | R16: =L16+P16 -> 41140 | S16: =P16 -> 7140 | T16: =S16 -> 7140 | U16: =T16 -> 7140 | V16: =U16 -> 7140 | W16: =V16 -> 7140 | X16: =IF(C16="R",L16,) -> 34000 | Y16: =V16 -> 7140 | Z16: =W16 -> 7140 | AA16: =Z16 -> 7140 | AB16: =AA16 -> 7140 | AC16: =SUM(R16:AB16) -> 139400
A17: =IF(W17>0,"x","") | B17: Link to Lawrenceville office | D17: MPLS | G17: 1 | J17: 0 | K17: 1000 | L17: =J17*K17 -> 0 | N17: =J17 -> 0 | O17: =12*1500 -> 18000 | P17: =N17*O17 -> 0 | R17: =L17+P17 -> 0 | S17: =P17 -> 0 | T17: =S17 -> 0 | U17: =T17 -> 0 | V17: =U17 -> 0 | W17: =V17 -> 0 | X17: =IF(C17="R",L17,) -> 0 | Y17: =V17 -> 0 | Z17: =W17 -> 0 | AA17: =Z17 -> 0 | AB17: =AA17 -> 0 | AC17: =SUM(R17:AB17) -> 0
A18: =IF(W18>0,"x","") | B18: Link to NJ State | D18: MPLS (VPN is used) | G18: 1 | J18: 0 | K18: 1000 | L18: =J18*K18 -> 0 | N18: =J18 -> 0 | O18: =12*1500 -> 18000 | P18: =N18*O18 -> 0 | R18: =L18+P18 -> 0 | S18: =P18 -> 0 | T18: =S18 -> 0 | U18: =T18 -> 0 | V18: =U18 -> 0 | W18: =V18 -> 0 | X18: =IF(C18="R",L18,) -> 0 | Y18: =V18 -> 0 | Z18: =W18 -> 0 | AA18: =Z18 -> 0 | AB18: =AA18 -> 0 | AC18: =SUM(R18:AB18) -> 0
A19: =IF(W19>0,"x","") -> x | B19: RDBMS Mgmt Option Packs | D19: GoldenGate (for Oracle Database) | E19: Oracle | G19: 0.5 | I19: 0.5 | J19: 6 | K19: 17500 | L19: =J19*K19*60% -> 63000 | M19: 40% Discount | N19: =J19 -> 6 | O19: =K19*22%*60% -> 2310 | P19: =O19*N19 -> 13860 | R19: =L19+P19 -> 76860 | S19: =P19 -> 13860 | T19: =S19 -> 13860 | U19: =T19 -> 13860 | V19: =U19 -> 13860 | W19: =V19 -> 13860 | X19: =IF(C19="R",L19,) -> 0 | Y19: =V19 -> 13860 | Z19: =W19 -> 13860 | AA19: =Z19 -> 13860 | AB19: =AA19 -> 13860 | AC19: =SUM(R19:AB19) -> 201600
A20: =IF(W20>0,"x","") -> x | B20: RDBMS Mgmt Option Packs | D20: GoldenGate Foundation Pack (Includes Veridata, Managament Pack & GG studio) | E20: Oracle | G20: 0.5 | I20: 0.5 | J20: 6 | K20: 7500 | L20: =J20*K20*60% -> 27000 | M20: 50% Discount | N20: =J20 -> 6 | O20: =K20*22%*60% -> 990 | P20: =O20*N20 -> 5940 | R20: =L20+P20 -> 32940 | S20: =P20 -> 5940 | T20: =S20 -> 5940 | U20: =T20 -> 5940 | V20: =U20 -> 5940 | W20: =V20 -> 5940 | X20: =IF(C20="R",L20,) -> 0 | Y20: =V20 -> 5940 | Z20: =W20 -> 5940 | AA20: =Z20 -> 5940 | AB20: =AA20 -> 5940 | AC20: =SUM(R20:AB20) -> 86400
A21: =IF(W21>0,"x","") -> x | B21: RDBMS Mgmt Option Packs | D21: Multitenant Option | E21: Oracle | G21: 0.5 | I21: 0.5 | J21: 6 | K21: 17500 | L21: =J21*K21*60% -> 63000 | M21: 50% Discount | N21: =J21 -> 6 | O21: =K21*22%*60% -> 2310 | P21: =O21*N21 -> 13860 | R21: =L21+P21 -> 76860 | S21: =P21 -> 13860 | T21: =S21 -> 13860 | U21: =T21 -> 13860 | V21: =U21 -> 13860 | W21: =V21 -> 13860 | X21: =IF(C21="R",L21,) -> 0 | Y21: =V21 -> 13860 | Z21: =W21 -> 13860 | AA21: =Z21 -> 13860 | AB21: =AA21 -> 13860 | AC21: =SUM(R21:AB21) -> 201600
A22: =IF(W22>0,"x","") -> x | B22: VIN Decoder | D22: Vin Power | E22: VINPower | G22: 1 | L22: =J22*K22 -> 0 | N22: 1 | O22: 13000 | P22: =O22*N22 -> 13000 | R22: =L22+P22 -> 13000 | S22: =P22 -> 13000 | T22: =S22 -> 13000 | U22: =T22 -> 13000 | V22: =U22 -> 13000 | W22: =V22 -> 13000 | X22: =IF(C22="R",L22,) -> 0 | Y22: =V22 -> 13000 | Z22: =W22 -> 13000 | AA22: =Z22 -> 13000 | AB22: =AA22 -> 13000 | AC22: =SUM(R22:AB22) -> 130000
A23: =IF(W23>0,"x","") -> x | B23: Business Intelligence | D23: Actuate, PROD, UAT, QAT, DEV | E23: Actuate | G23: 1 | J23: 1 | K23: =268619.25 -> 268619.25 | L23: =J23*K23 -> 268619.25 | N23: 1 | O23: =K23*20% -> 53723.85 | P23: =O23*N23 -> 53723.85 | R23: =L23+P23 -> 322343.1 | S23: =P23 -> 53723.85 | T23: =S23 -> 53723.85 | U23: =T23 -> 53723.85 | V23: =U23 -> 53723.85 | W23: =V23 -> 53723.85 | X23: =IF(C23="R",L23,) -> 0 | Y23: =V23 -> 53723.85 | Z23: =W23 -> 53723.85 | AA23: =Z23 -> 53723.85 | AB23: =AA23 -> 53723.85 | AC23: =SUM(R23:AB23) -> 805857.75
A24: =IF(W24>0,"x","") -> x | B24: Linux subscription | D24: Satellite server | E24: RedHat | G24: 1 | L24: =J24*K24 -> 0 | N24: 1 | O24: 10000 | P24: =O24*N24 -> 10000 | R24: =L24+P24 -> 10000 | S24: =P24 -> 10000 | T24: =S24 -> 10000 | U24: =T24 -> 10000 | V24: =U24 -> 10000 | W24: =V24 -> 10000 | X24: =IF(C24="R",L24,) -> 0 | Y24: =V24 -> 10000 | Z24: =W24 -> 10000 | AA24: =Z24 -> 10000 | AB24: =AA24 -> 10000 | AC24: =SUM(R24:AB24) -> 100000
A25: =IF(W25>0,"x","") -> x | B25: Linux subscription | D25: Satellite server client license | E25: RedHat | G25: 1 | L25: =J25*K25 -> 0 | N25: 200 | O25: 192 | P25: =O25*N25 -> 38400 | R25: =L25+P25 -> 38400 | S25: =P25 -> 38400 | T25: =S25 -> 38400 | U25: =T25 -> 38400 | V25: =U25 -> 38400 | W25: =V25 -> 38400 | X25: =IF(C25="R",L25,) -> 0 | Y25: =V25 -> 38400 | Z25: =W25 -> 38400 | AA25: =Z25 -> 38400 | AB25: =AA25 -> 38400 | AC25: =SUM(R25:AB25) -> 384000
A26: =IF(W26>0,"x","") | B26: Windows Server | D26: Datacenter edition | E26: Microsoft | G26: 0.5 | I26: 0.5 | J26: 2 | K26: 5000 | L26: =J26*K26 -> 10000 | N26: =J26 -> 2 | P26: =O26*N26 -> 0 | R26: =L26+P26 -> 10000 | S26: =P26 -> 0 | T26: =S26 -> 0 | U26: =T26 -> 0 | V26: =U26 -> 0 | W26: =V26 -> 0 | X26: =IF(C26="R",L26,) -> 0 | Y26: =V26 -> 0 | Z26: =W26 -> 0 | AA26: =Z26 -> 0 | AB26: =AA26 -> 0 | AC26: =SUM(R26:AB26) -> 10000
A27: =IF(W27>0,"x","") | B27: Virus Scanner (Windows Defender) | D27: Virus/Malware scanner for test units | E27: Microsoft | G27: 1 | L27: =J27*K27 -> 0 | N27: 0 | O27: 32 | P27: =O27*N27 -> 0 | R27: =L27+P27 -> 0 | S27: =P27 -> 0 | T27: =S27 -> 0 | U27: =T27 -> 0 | V27: =U27 -> 0 | W27: =V27 -> 0 | X27: =IF(C27="R",L27,) -> 0 | Y27: =V27 -> 0 | Z27: =W27 -> 0 | AA27: =Z27 -> 0 | AB27: =AA27 -> 0 | AC27: =SUM(R27:AB27) -> 0
A28: =IF(W28>0,"x","") -> x | B28: Mobile Device Management | D28: Device management for Windows 10 devices | E28: Soti | G28: 1 | L28: =J28*K28 -> 0 | N28: 1400 | O28: 36 | P28: =O28*N28 -> 50400 | R28: =L28+P28 -> 50400 | S28: =P28 -> 50400 | T28: =S28 -> 50400 | U28: =T28 -> 50400 | V28: =U28 -> 50400 | W28: =V28 -> 50400 | X28: =IF(C28="R",L28,) -> 0 | Y28: =V28 -> 50400 | Z28: =W28 -> 50400 | AA28: =Z28 -> 50400 | AB28: =AA28 -> 50400 | AC28: =SUM(R28:AB28) -> 504000
A29: =IF(W29>0,"x","") -> x | B29: Backup Software | D29: NetBackup - migration to SPARC platform | E29: Symantec | G29: 0.5 | I29: 0.5 | J29: 1 | K29: 8000 | L29: =J29*K29 -> 8000 | N29: =J29 -> 1 | O29: 2000 | P29: =O29*N29 -> 2000 | R29: =L29+P29 -> 10000 | S29: =P29 -> 2000 | T29: =S29 -> 2000 | U29: =T29 -> 2000 | V29: =U29 -> 2000 | W29: =V29 -> 2000 | X29: =IF(C29="R",L29,) -> 0 | Y29: =V29 -> 2000 | Z29: =W29 -> 2000 | AA29: =Z29 -> 2000 | AB29: =AA29 -> 2000 | AC29: =SUM(R29:AB29) -> 28000
A30: =IF(W30>0,"x","") -> x | B30: Backup client licenses | D30: Netbackup Enterprise Client (LDOMs) | E30: Symantec | G30: 0.5 | I30: 0.5 | J30: 2 | K30: 2000 | L30: =J30*K30 -> 4000 | N30: =J30 -> 2 | O30: =20%*K30 -> 400 | P30: =O30*N30 -> 800 | R30: =L30+P30 -> 4800 | S30: =P30 -> 800 | T30: =S30 -> 800 | U30: =T30 -> 800 | V30: =U30 -> 800 | W30: =V30 -> 800 | X30: =IF(C30="R",L30,) -> 0 | Y30: =V30 -> 800 | Z30: =W30 -> 800 | AA30: =Z30 -> 800 | AB30: =AA30 -> 800 | AC30: =SUM(R30:AB30) -> 12000
A31: =IF(W31>0,"x","") -> x | B31: RDBMS Mgmt Option Packs | D31: GoldenGate (for Oracle Database) | E31: Oracle | G31: 0.5 | I31: 0.5 | J31: 150 | K31: 350 | L31: =J31*K31*60% -> 31500 | M31: 40% Discount | N31: =J31 -> 150 | O31: =K31*22%*60% -> 46.2 | P31: =O31*N31 -> 6930 | R31: =L31+P31 -> 38430 | S31: =P31 -> 6930 | T31: =S31 -> 6930 | U31: =T31 -> 6930 | V31: =U31 -> 6930 | W31: =V31 -> 6930 | X31: =IF(C31="R",L31,) -> 0 | Y31: =V31 -> 6930 | Z31: =W31 -> 6930 | AA31: =Z31 -> 6930 | AB31: =AA31 -> 6930 | AC31: =SUM(R31:AB31) -> 100800
A32: =IF(W32>0,"x","") -> x | B32: RDBMS Mgmt Option Packs | D32: GoldenGate Foundation Pack (Includes Veridata, Managament Pack & GG studio) | E32: Oracle | G32: 0.5 | I32: 0.5 | J32: 150 | K32: 150 | L32: =J32*K32*60% -> 13500 | M32: 50% Discount | N32: =J32 -> 150 | O32: =K32*22%*60% -> 19.8 | P32: =O32*N32 -> 2970 | R32: =L32+P32 -> 16470 | S32: =P32 -> 2970 | T32: =S32 -> 2970 | U32: =T32 -> 2970 | V32: =U32 -> 2970 | W32: =V32 -> 2970 | X32: =IF(C32="R",L32,) -> 0 | Y32: =V32 -> 2970 | Z32: =W32 -> 2970 | AA32: =Z32 -> 2970 | AB32: =AA32 -> 2970 | AC32: =SUM(R32:AB32) -> 43200
